<?xml version="1.0" ?>
<robot name="AHR" xmlns:xacro="http://ros.org/wiki/xacro">
 <xacro:include filename="$(find turtlebot3_description)/urdf/common_properties.xacro"/>



  <link name="base_footprint"/>

  <joint name="base_joint" type="fixed">
    <parent link="base_footprint"/>
    <child link="base_link" />
    <origin xyz="-0.31 0.15 -0.22" rpy="0 0 0"/>
  </joint>


  <link name="base_link">
<!-- 시각적 형체 -->
    <visual>
      <origin xyz="0.131 -0.302 -0.155" rpy="1.57079632679 0.27 3.141692"/>       <!-- 위치 -->
      <geometry> 
        <mesh filename="package://urdf_ahr/AHR_URDF/base.stl" scale="0.001 0.001 0.001"/>
      </geometry>
      <material name="base_link">
        <color rgba= "0.80 0.80 0.80 1"/>
      </material>
    </visual>
<!-- 물리적 히트박스 -->
    <collision> 
      <origin xyz="0 0.0 0" rpy="0 0 0"/>
       <!-- <origin xyz="0 0 0.035" rpy="0 0 0"/> -->
      <geometry>
        <box size="0.575 0.40 0.31"/>      <!-- 로봇 사이즈 (박스로) -->
      </geometry>
    </collision>
<!-- 물리적 특성 -->
    <inertial>
      <origin xyz="0 0 0" rpy="0 0 0"/>
      <mass value="0"/>      <!-- 질량 -->
      <inertia ixx="0.0" ixy="0.0" ixz="0.0"
               iyy="0.0" iyz="0.0"
               izz="0.0" />
    </inertial>
  </link>


<!-- 111111111111111111111111111111111111111111111111111111111111111111111 -->

  <joint name="wheel_left_joint" type="continuous">
    <parent link="base_link"/>
    <child link="wheel_left_link"/>
    <origin xyz="0.48 0.08 -0.33" rpy="-1.57079632679 0 0"/>
    <axis xyz="0 0 1"/>
  </joint>

  <link name="wheel_left_link">
    <visual>
      <origin xyz="0 0.06 0" rpy="1.57079632679 0 0"/>
      <geometry>
        <mesh filename="package://urdf_ahr/AHR_URDF/wheel.stl" />
      </geometry>
      <material name="wheel_left_link">
      <color rgba= "0.2 0.2 0.2 1"/>
      </material>
    </visual>

    <collision>
      <origin xyz="0 0.06 0" rpy="1.57079632679 0 0"/>
      <geometry>
        <cylinder length="0.06" radius="0.065"/>  <!-- length="길이(두께)" radius="반지름 -->
      </geometry>
    </collision>

    <inertial>
      <origin xyz="0 0 0" />
      <mass value="0" />
      <inertia ixx="0.0" ixy="0.0" ixz="0.0"
               iyy="0.0" iyz="0.0"
               izz="0.0" />
    </inertial>
  </link>

<!-- 2222222222222222222222222222222222222222222222222222222222222222222222 -->

  <joint name="wheel_right_joint" type="continuous">
    <parent link="base_link"/>
    <child link="wheel_right_link"/>
    <origin xyz="0.48 -0.375 -0.33" rpy="-1.57079632679 0 0"/>
    <axis xyz="0 0 1"/>
  </joint>

  <link name="wheel_right_link">
    <visual>
      <origin xyz="0 0.06 -0.06" rpy="1.57079632679 0 0"/>
      <geometry>
        <mesh filename="package://urdf_ahr/AHR_URDF/wheel.stl" />
      </geometry>
      <material name="wheel_right_link">
      <color rgba= "0.2 0.2 0.2 1"/>
      </material>
    </visual>

    <collision>
      <origin xyz="0 0.06 -0.06" rpy="1.57079632679 0 0"/>
      <geometry>
        <cylinder length="0.06" radius="0.065"/>  <!-- length="길이(두께)" radius="반지름 -->
      </geometry>
    </collision>

    <inertial>
      <origin xyz="0 0 0" />
      <mass value="0" />
      <inertia ixx="0.0" ixy="0.0" ixz="0.0"
               iyy="0.0" iyz="0.0"
               izz="0.0" />
    </inertial>
  </link>

<!-- 333333333333333333333333333333333333333333333333333333333333333333333333333 -->

  <joint name="wheel_left_C_joint" type="continuous">
    <parent link="base_link"/>
    <child link="wheel_left_C_link"/>
    <origin xyz="0.12 0.08 -0.33" rpy="-1.57079632679 0 0"/>
    <axis xyz="0 0 1"/>
  </joint>

  <link name="wheel_left_C_link">
    <visual>
      <origin xyz="0 0.06 0" rpy="1.57079632679 0 0"/>
      <geometry>
        <mesh filename="package://urdf_ahr/AHR_URDF/wheel.stl" />
      </geometry>
      <material name="wheel_left_C_link">
      <color rgba= "0.2 0.2 0.2 1"/>
      </material>
    </visual>

    <collision>
      <origin xyz="0 0.06 0" rpy="1.57079632679 0 0"/>
      <geometry>
        <cylinder length="0.06" radius="0.065"/>  <!-- length="길이(두께)" radius="반지름 -->
      </geometry>
    </collision>

    <inertial>
      <origin xyz="0 0 0" />
      <mass value="0" />
      <inertia ixx="0.0" ixy="0.0" ixz="0.0"
               iyy="0.0" iyz="0.0"
               izz="0.0" />
    </inertial>
  </link>

<!-- 44444444444444444444444444444444444444444444444444444444444444444444444 -->

<joint name="wheel_right_C_joint" type="continuous">
    <parent link="base_link"/>
    <child link="wheel_right_C_link"/>
    <origin xyz="0.12 -0.375 -0.33" rpy="-1.57079632679 0 0"/>
    <axis xyz="0 0 1"/>
  </joint>

  <link name="wheel_right_C_link">
    <visual>
      <origin xyz="0 0.06 -0.06" rpy="1.57079632679 0 0"/>
      <geometry>
        <mesh filename="package://urdf_ahr/AHR_URDF/wheel.stl" />
      </geometry>
      <material name="wheel_right_C_link">
      <color rgba= "0.2 0.2 0.2 1"/>
      </material>
    </visual>

    <collision>
      <origin xyz="0 0.06 -0.06" rpy="1.57079632679 0 0"/>
      <geometry>
        <cylinder length="0.06" radius="0.065"/>  <!-- length="길이(두께)" radius="반지름 -->
      </geometry>
    </collision>

    <inertial>
      <origin xyz="0 0 0" />
      <mass value="0" />
      <inertia ixx="0.0" ixy="0.0" ixz="0.0"
               iyy="0.0" iyz="0.0"
               izz="0.0" />
    </inertial>
  </link>

<!-- 5555555555555555555555555555555555555555555555555555555555555555555555555 -->

  <joint name="wheel_left_R_joint" type="continuous">
    <parent link="base_link"/>
    <child link="wheel_left_R_link"/>
    <origin xyz="-0.17 0.08 -0.33" rpy="-1.57079632679 0 0"/>
    <axis xyz="0 0 1"/>
  </joint>

  <link name="wheel_left_R_link">
    <visual>
      <origin xyz="0 0.06 0" rpy="1.57079632679 0 0"/>
      <geometry>
        <mesh filename="package://urdf_ahr/AHR_URDF/wheel.stl" />
      </geometry>
      <material name="wheel_left_R_link">
      <color rgba= "0.2 0.2 0.2 1"/>
      </material>
    </visual>

    <collision>
      <origin xyz="0 0.06 0" rpy="1.57079632679 0 0"/>
      <geometry>
        <cylinder length="0.06" radius="0.065"/>  <!-- length="길이(두께)" radius="반지름 -->
      </geometry>
    </collision>

    <inertial>
      <origin xyz="0 0 0" />
      <mass value="0" />
      <inertia ixx="0.0" ixy="0.0" ixz="0.0"
               iyy="0.0" iyz="0.0"
               izz="0.0" />
    </inertial>
  </link>

<!-- 666666666666666666666666666666666666666666666666666666666666666666 -->

 <joint name="wheel_right_R_joint" type="continuous">
    <parent link="base_link"/>
    <child link="wheel_right_R_link"/>
    <origin xyz="-0.17 -0.385 -0.33" rpy="-1.57079632679 0 0"/>
    <axis xyz="0 0 1"/>
  </joint>

  <link name="wheel_right_R_link">
    <visual>
      <origin xyz="0 0.06 -0.06" rpy="1.57079632679 0 0"/>
      <geometry>
        <mesh filename="package://urdf_ahr/AHR_URDF/wheel.stl" />
      </geometry>
      <material name="wheel_right_R_link">
      <color rgba= "0.2 0.2 0.2 1"/>
      </material>
    </visual>

    <collision>
      <origin xyz="0 0.06 -0.06" rpy="1.57079632679 0 0"/>
      <geometry>
        <cylinder length="0.06" radius="0.065"/>  <!-- length="길이(두께)" radius="반지름 -->
      </geometry>
    </collision>

    <inertial>
      <origin xyz="0 0 0" />
      <mass value="0" />
      <inertia ixx="0.0" ixy="0.0" ixz="0.0"
               iyy="0.0" iyz="0.0"
               izz="0.0" />
    </inertial>
  </link>



<!-- imu(opencr) -->

  <joint name="imu_joint" type="fixed">
    <parent link="base_link"/>
    <child link="imu_link"/>
    <origin xyz="0 0 0" rpy="0 0 0"/>
  </joint>

  <link name="imu_link">
    <visual>
      <origin xyz="0.015 0 0" rpy="0 0 1.57"/>
      <geometry>
        <mesh filename="package://urdf_ahr/AHR_URDF/OpenCR_REVH.stl" scale="0.001 0.001 0.001"/>
      </geometry>
      <material name="dark">
      <color rgba="0.3 0.3 0.3 1.0"/>
      </material>
    </visual>

    <collision>
      <origin xyz="0 0 0" rpy="0 0 0"/>
      <geometry>
        <cylinder length="0.0315" radius="0.055"/>
      </geometry>
    </collision>

    <inertial>
      <mass value="0" />
      <origin xyz="0 0 0" />
      <inertia ixx="0.001" ixy="0.0" ixz="0.0"
               iyy="0.001" iyz="0.0"
               izz="0.001" />
    </inertial>
  </link>




<!-- LDS -->

  <joint name="scan_joint" type="fixed">
    <parent link="base_link"/>
    <child link="base_scan"/>
    <origin xyz="0.31 -0.15 0.121" rpy="0 0 0"/>
  </joint>


  <link name="base_scan">
    <visual>
      <origin xyz="0 0 0" rpy="1.57 0 0"/>
      <geometry>
        <mesh filename="package://urdf_ahr/AHR_URDF/hokuyo_utm30lx.stl" scale="0.001 0.001 0.001"/>
      </geometry>
    <material name="dark">
    <color rgba="0.3 0.3 0.3 1.0"/>
    </material>
    </visual>

    <collision>
      <origin xyz="0 0 0" rpy="0 0 0"/>
      <geometry>
        <cylinder length="0.0315" radius="0.055"/>
      </geometry>
    </collision>

    <inertial>
      <mass value="0" />
      <origin xyz="0 0 0" />
      <inertia ixx="0.001" ixy="0.0" ixz="0.0"
               iyy="0.001" iyz="0.0"
               izz="0.001" />
    </inertial>
  </link>



<!-- 판 -->

 <joint name="board_joint" type="fixed">
    <parent link="base_link"/>
    <child link="board_link"/>
    <origin xyz="0.15 -0.15 0.12" rpy="0 0 0"/>
    <axis xyz="0 1 0"/>
  </joint>

  <link name="board_link">
    <visual>
      <origin xyz="0 -0.2 0" rpy="3.141592 0 0"/>
      <geometry>
        <mesh filename="package://urdf_ahr/AHR_URDF/board.stl" />
      </geometry>
      <material name="base_link">
        <color rgba= "0.80 0.80 0.80 1"/>
      </material>
    </visual>

    <collision>
      <origin xyz="0 -0.2 0" rpy="3.141592 0 0"/>
      <geometry>
        <cylinder length="0.06" radius="0.065"/>  <!-- length="길이(두께)" radius="반지름 -->
      </geometry>
    </collision>

    <inertial>
      <origin xyz="0 0 0" />
      <mass value="0" />
      <inertia ixx="0.0" ixy="0.0" ixz="0.0"
               iyy="0.0" iyz="0.0"
               izz="0.0" />
    </inertial>
  </link>


<!-- ZED2 -->

 <joint name="zed_joint" type="fixed">
    <parent link="base_link"/>
    <child link="zed_base_link"/>
    <origin xyz="0.31 -0.15 0.22" rpy="0 0 0"/>
    <axis xyz="0 1 0"/>
  </joint>

  <link name="zed_base_link">
    <visual>
      <origin xyz="0 0 0" rpy="0 0 0"/>
      <geometry>
        <mesh filename="package://urdf_ahr/AHR_URDF/zed2.stl" />
      </geometry>
      <material name="zed_base_link">
        <color rgba= "0.80 0.80 0.80 0"/>
      </material>
    </visual>

    <collision>
      <origin xyz="0 0 0" rpy="0 0 0"/>
      <geometry>
        <cylinder length="0.06" radius="0.065"/>  <!-- length="길이(두께)" radius="반지름 -->
      </geometry>
    </collision>

    <inertial>
      <origin xyz="0 0 0" />
      <mass value="0" />
      <inertia ixx="0.0" ixy="0.0" ixz="0.0"
               iyy="0.0" iyz="0.0"
               izz="0.0" />
    </inertial>
  </link>


</robot>